{
 "cells": [
  {
   "cell_type": "code",
   "execution_count": 19,
   "id": "fd203d7e",
   "metadata": {},
   "outputs": [],
   "source": [
    "import numpy as np\n",
    "import pandas as pd\n",
    "import cv2\n",
    "import os\n",
    "import time\n",
    "# import keras.layers as kr\n",
    "from tqdm import tqdm\n",
    "import matplotlib.pyplot as plt\n",
    "import pickle\n",
    "\n",
    "from keras.models import Model\n",
    "from keras.applications.resnet import *\n",
    "# from keras.preprocessing.image_dataset import *\n",
    "from keras.preprocessing import image\n",
    "import random\n",
    "from tensorflow.keras import layers\n",
    "import tensorflow as tf"
   ]
  },
  {
   "cell_type": "code",
   "execution_count": 3,
   "id": "e1994e18",
   "metadata": {},
   "outputs": [],
   "source": [
    "train = pd.read_csv('validate_train.csv').values\n",
    "validate = pd.read_csv('validate.csv').values"
   ]
  },
  {
   "cell_type": "code",
   "execution_count": 6,
   "id": "c7608d3f",
   "metadata": {},
   "outputs": [
    {
     "data": {
      "text/plain": [
       "array([['IMG2744_1', -9.380678081, 3.58271965],\n",
       "       ['IMG2744_2', -9.380678081, 3.58271965],\n",
       "       ['IMG2744_3', -9.380678081, 3.58271965],\n",
       "       ...,\n",
       "       ['IMG4243_3', -4.680678082, 35.18271965],\n",
       "       ['IMG4243_4', -4.680678082, 35.18271965],\n",
       "       ['IMG4243_5', -4.680678082, 35.18271965]], dtype=object)"
      ]
     },
     "execution_count": 6,
     "metadata": {},
     "output_type": "execute_result"
    }
   ],
   "source": [
    "train"
   ]
  },
  {
   "cell_type": "code",
   "execution_count": 7,
   "id": "c7644411",
   "metadata": {},
   "outputs": [
    {
     "data": {
      "text/plain": [
       "array([['IMG3914_5', 23.41932192, 1.38271965],\n",
       "       ['IMG2810_2', 55.51932192, -47.51728035],\n",
       "       ['IMG3622_2', 51.81932192, -9.41728035],\n",
       "       ...,\n",
       "       ['IMG4013_3', -9.180678082, 38.58271965],\n",
       "       ['IMG4116_2', -63.18067808, 59.88271965],\n",
       "       ['IMG3674_5', -4.080678082, -16.21728035]], dtype=object)"
      ]
     },
     "execution_count": 7,
     "metadata": {},
     "output_type": "execute_result"
    }
   ],
   "source": [
    "validate"
   ]
  },
  {
   "cell_type": "code",
   "execution_count": 13,
   "id": "d63be112",
   "metadata": {},
   "outputs": [],
   "source": [
    "validate_file = open(f'./validate_resnet101.pckl','rb')\n",
    "train_file = open(f'./validate_train_resnet101.pckl','rb')"
   ]
  },
  {
   "cell_type": "code",
   "execution_count": 14,
   "id": "c43a4b9a",
   "metadata": {},
   "outputs": [],
   "source": [
    "train_resnet101 = pickle.load(train_file)\n",
    "validate_resnet101 = pickle.load(validate_file)"
   ]
  },
  {
   "cell_type": "code",
   "execution_count": 69,
   "id": "bcc003a1",
   "metadata": {},
   "outputs": [],
   "source": [
    "from sklearn.ensemble import RandomForestClassifier"
   ]
  },
  {
   "cell_type": "code",
   "execution_count": 105,
   "id": "81e2ceee",
   "metadata": {},
   "outputs": [],
   "source": [
    "clf = RandomForestClassifier()\n",
    "\n",
    "train = np.array(train_resnet101).reshape(6900,2048)\n",
    "validate = np.array(validate_resnet101).reshape(600,2048)\n",
    "\n",
    "inp = [0]*6900\n",
    "out = [1]*600"
   ]
  },
  {
   "cell_type": "code",
   "execution_count": 106,
   "id": "03d3a0dc",
   "metadata": {},
   "outputs": [
    {
     "data": {
      "text/plain": [
       "0.0"
      ]
     },
     "execution_count": 106,
     "metadata": {},
     "output_type": "execute_result"
    }
   ],
   "source": [
    "clf.fit(train,inp)\n",
    "y = clf.score(validate,out)\n",
    "y"
   ]
  },
  {
   "cell_type": "code",
   "execution_count": 108,
   "id": "1e10736d",
   "metadata": {},
   "outputs": [],
   "source": [
    "full_train = open(f'./train_resnet101.pckl','rb')\n",
    "full_train = pickle.read\n",
    "full_test = open(f'./test_resnet101.pckl','rb')"
   ]
  },
  {
   "cell_type": "code",
   "execution_count": 109,
   "id": "3e96bea0",
   "metadata": {},
   "outputs": [
    {
     "data": {
      "text/plain": [
       "<_io.BufferedReader name='./train_resnet101.pckl'>"
      ]
     },
     "execution_count": 109,
     "metadata": {},
     "output_type": "execute_result"
    },
    {
     "name": "stdout",
     "output_type": "stream",
     "text": [
      "ERROR! Session/line number was not unique in database. History logging moved to new session 321\n"
     ]
    }
   ],
   "source": [
    "full_train"
   ]
  },
  {
   "cell_type": "code",
   "execution_count": null,
   "id": "c3cf6266",
   "metadata": {},
   "outputs": [
    {
     "name": "stderr",
     "output_type": "stream",
     "text": [
      "ERROR:root:Internal Python error in the inspect module.\n",
      "Below is the traceback from this internal error.\n",
      "\n",
      "ERROR:root:Internal Python error in the inspect module.\n",
      "Below is the traceback from this internal error.\n",
      "\n",
      "ERROR:root:Internal Python error in the inspect module.\n",
      "Below is the traceback from this internal error.\n",
      "\n"
     ]
    },
    {
     "name": "stdout",
     "output_type": "stream",
     "text": [
      "Traceback (most recent call last):\n",
      "  File \"D:\\Anaconda\\envs\\CV\\lib\\site-packages\\IPython\\core\\interactiveshell.py\", line 3441, in run_code\n",
      "    exec(code_obj, self.user_global_ns, self.user_ns)\n",
      "  File \"C:\\Users\\USER\\AppData\\Local\\Temp/ipykernel_2520/4039413926.py\", line 3, in <module>\n",
      "    full_train = np.array(full_train).reshape(7500,2048)\n",
      "ValueError: cannot reshape array of size 1 into shape (7500,2048)\n",
      "\n",
      "During handling of the above exception, another exception occurred:\n",
      "\n",
      "Traceback (most recent call last):\n",
      "  File \"D:\\Anaconda\\envs\\CV\\lib\\site-packages\\IPython\\core\\interactiveshell.py\", line 2061, in showtraceback\n",
      "    stb = value._render_traceback_()\n",
      "AttributeError: 'ValueError' object has no attribute '_render_traceback_'\n",
      "\n",
      "During handling of the above exception, another exception occurred:\n",
      "\n",
      "Traceback (most recent call last):\n",
      "  File \"D:\\Anaconda\\envs\\CV\\lib\\site-packages\\IPython\\core\\ultratb.py\", line 1101, in get_records\n",
      "    return _fixed_getinnerframes(etb, number_of_lines_of_context, tb_offset)\n",
      "  File \"D:\\Anaconda\\envs\\CV\\lib\\site-packages\\IPython\\core\\ultratb.py\", line 248, in wrapped\n",
      "    return f(*args, **kwargs)\n",
      "  File \"D:\\Anaconda\\envs\\CV\\lib\\site-packages\\IPython\\core\\ultratb.py\", line 281, in _fixed_getinnerframes\n",
      "    records = fix_frame_records_filenames(inspect.getinnerframes(etb, context))\n",
      "  File \"D:\\Anaconda\\envs\\CV\\lib\\inspect.py\", line 1502, in getinnerframes\n",
      "    frameinfo = (tb.tb_frame,) + getframeinfo(tb, context)\n",
      "  File \"D:\\Anaconda\\envs\\CV\\lib\\inspect.py\", line 1460, in getframeinfo\n",
      "    filename = getsourcefile(frame) or getfile(frame)\n",
      "  File \"D:\\Anaconda\\envs\\CV\\lib\\inspect.py\", line 696, in getsourcefile\n",
      "    if getattr(getmodule(object, filename), '__loader__', None) is not None:\n",
      "  File \"D:\\Anaconda\\envs\\CV\\lib\\inspect.py\", line 733, in getmodule\n",
      "    if ismodule(module) and hasattr(module, '__file__'):\n",
      "  File \"D:\\Anaconda\\envs\\CV\\lib\\site-packages\\tensorflow\\__init__.py\", line 50, in __getattr__\n",
      "    module = self._load()\n",
      "  File \"D:\\Anaconda\\envs\\CV\\lib\\site-packages\\tensorflow\\__init__.py\", line 44, in _load\n",
      "    module = _importlib.import_module(self.__name__)\n",
      "  File \"D:\\Anaconda\\envs\\CV\\lib\\importlib\\__init__.py\", line 127, in import_module\n",
      "    return _bootstrap._gcd_import(name[level:], package, level)\n",
      "  File \"<frozen importlib._bootstrap>\", line 1006, in _gcd_import\n",
      "  File \"<frozen importlib._bootstrap>\", line 983, in _find_and_load\n",
      "  File \"<frozen importlib._bootstrap>\", line 965, in _find_and_load_unlocked\n",
      "ModuleNotFoundError: No module named 'tensorflow_core.estimator'\n",
      "Traceback (most recent call last):\n",
      "  File \"D:\\Anaconda\\envs\\CV\\lib\\site-packages\\IPython\\core\\interactiveshell.py\", line 3441, in run_code\n",
      "    exec(code_obj, self.user_global_ns, self.user_ns)\n",
      "  File \"C:\\Users\\USER\\AppData\\Local\\Temp/ipykernel_2520/4039413926.py\", line 3, in <module>\n",
      "    full_train = np.array(full_train).reshape(7500,2048)\n",
      "ValueError: cannot reshape array of size 1 into shape (7500,2048)\n",
      "\n",
      "During handling of the above exception, another exception occurred:\n",
      "\n",
      "Traceback (most recent call last):\n",
      "  File \"D:\\Anaconda\\envs\\CV\\lib\\site-packages\\IPython\\core\\interactiveshell.py\", line 2061, in showtraceback\n",
      "    stb = value._render_traceback_()\n",
      "AttributeError: 'ValueError' object has no attribute '_render_traceback_'\n",
      "\n",
      "During handling of the above exception, another exception occurred:\n",
      "\n",
      "Traceback (most recent call last):\n",
      "  File \"D:\\Anaconda\\envs\\CV\\lib\\site-packages\\IPython\\core\\interactiveshell.py\", line 3361, in run_ast_nodes\n",
      "    if (await self.run_code(code, result,  async_=asy)):\n",
      "  File \"D:\\Anaconda\\envs\\CV\\lib\\site-packages\\IPython\\core\\interactiveshell.py\", line 3458, in run_code\n",
      "    self.showtraceback(running_compiled_code=True)\n",
      "  File \"D:\\Anaconda\\envs\\CV\\lib\\site-packages\\IPython\\core\\interactiveshell.py\", line 2064, in showtraceback\n",
      "    value, tb, tb_offset=tb_offset)\n",
      "  File \"D:\\Anaconda\\envs\\CV\\lib\\site-packages\\IPython\\core\\ultratb.py\", line 1368, in structured_traceback\n",
      "    self, etype, value, tb, tb_offset, number_of_lines_of_context)\n",
      "  File \"D:\\Anaconda\\envs\\CV\\lib\\site-packages\\IPython\\core\\ultratb.py\", line 1268, in structured_traceback\n",
      "    self, etype, value, tb, tb_offset, number_of_lines_of_context\n",
      "  File \"D:\\Anaconda\\envs\\CV\\lib\\site-packages\\IPython\\core\\ultratb.py\", line 1125, in structured_traceback\n",
      "    tb_offset)\n",
      "  File \"D:\\Anaconda\\envs\\CV\\lib\\site-packages\\IPython\\core\\ultratb.py\", line 1082, in format_exception_as_a_whole\n",
      "    last_unique, recursion_repeat = find_recursion(orig_etype, evalue, records)\n",
      "  File \"D:\\Anaconda\\envs\\CV\\lib\\site-packages\\IPython\\core\\ultratb.py\", line 382, in find_recursion\n",
      "    return len(records), 0\n",
      "TypeError: object of type 'NoneType' has no len()\n",
      "\n",
      "During handling of the above exception, another exception occurred:\n",
      "\n",
      "Traceback (most recent call last):\n",
      "  File \"D:\\Anaconda\\envs\\CV\\lib\\site-packages\\IPython\\core\\interactiveshell.py\", line 2061, in showtraceback\n",
      "    stb = value._render_traceback_()\n",
      "AttributeError: 'TypeError' object has no attribute '_render_traceback_'\n",
      "\n",
      "During handling of the above exception, another exception occurred:\n",
      "\n",
      "Traceback (most recent call last):\n",
      "  File \"D:\\Anaconda\\envs\\CV\\lib\\site-packages\\IPython\\core\\ultratb.py\", line 1101, in get_records\n",
      "    return _fixed_getinnerframes(etb, number_of_lines_of_context, tb_offset)\n",
      "  File \"D:\\Anaconda\\envs\\CV\\lib\\site-packages\\IPython\\core\\ultratb.py\", line 248, in wrapped\n",
      "    return f(*args, **kwargs)\n",
      "  File \"D:\\Anaconda\\envs\\CV\\lib\\site-packages\\IPython\\core\\ultratb.py\", line 281, in _fixed_getinnerframes\n",
      "    records = fix_frame_records_filenames(inspect.getinnerframes(etb, context))\n",
      "  File \"D:\\Anaconda\\envs\\CV\\lib\\inspect.py\", line 1502, in getinnerframes\n",
      "    frameinfo = (tb.tb_frame,) + getframeinfo(tb, context)\n",
      "  File \"D:\\Anaconda\\envs\\CV\\lib\\inspect.py\", line 1460, in getframeinfo\n",
      "    filename = getsourcefile(frame) or getfile(frame)\n",
      "  File \"D:\\Anaconda\\envs\\CV\\lib\\inspect.py\", line 696, in getsourcefile\n",
      "    if getattr(getmodule(object, filename), '__loader__', None) is not None:\n",
      "  File \"D:\\Anaconda\\envs\\CV\\lib\\inspect.py\", line 733, in getmodule\n",
      "    if ismodule(module) and hasattr(module, '__file__'):\n",
      "  File \"D:\\Anaconda\\envs\\CV\\lib\\site-packages\\tensorflow\\__init__.py\", line 50, in __getattr__\n",
      "    module = self._load()\n",
      "  File \"D:\\Anaconda\\envs\\CV\\lib\\site-packages\\tensorflow\\__init__.py\", line 44, in _load\n",
      "    module = _importlib.import_module(self.__name__)\n",
      "  File \"D:\\Anaconda\\envs\\CV\\lib\\importlib\\__init__.py\", line 127, in import_module\n",
      "    return _bootstrap._gcd_import(name[level:], package, level)\n",
      "  File \"<frozen importlib._bootstrap>\", line 1006, in _gcd_import\n",
      "  File \"<frozen importlib._bootstrap>\", line 983, in _find_and_load\n",
      "  File \"<frozen importlib._bootstrap>\", line 965, in _find_and_load_unlocked\n",
      "ModuleNotFoundError: No module named 'tensorflow_core.estimator'\n",
      "Traceback (most recent call last):\n",
      "  File \"D:\\Anaconda\\envs\\CV\\lib\\site-packages\\IPython\\core\\interactiveshell.py\", line 3441, in run_code\n",
      "    exec(code_obj, self.user_global_ns, self.user_ns)\n",
      "  File \"C:\\Users\\USER\\AppData\\Local\\Temp/ipykernel_2520/4039413926.py\", line 3, in <module>\n",
      "    full_train = np.array(full_train).reshape(7500,2048)\n",
      "ValueError: cannot reshape array of size 1 into shape (7500,2048)\n",
      "\n",
      "During handling of the above exception, another exception occurred:\n",
      "\n",
      "Traceback (most recent call last):\n",
      "  File \"D:\\Anaconda\\envs\\CV\\lib\\site-packages\\IPython\\core\\interactiveshell.py\", line 2061, in showtraceback\n",
      "    stb = value._render_traceback_()\n",
      "AttributeError: 'ValueError' object has no attribute '_render_traceback_'\n",
      "\n",
      "During handling of the above exception, another exception occurred:\n",
      "\n",
      "Traceback (most recent call last):\n",
      "  File \"D:\\Anaconda\\envs\\CV\\lib\\site-packages\\IPython\\core\\interactiveshell.py\", line 3361, in run_ast_nodes\n",
      "    if (await self.run_code(code, result,  async_=asy)):\n",
      "  File \"D:\\Anaconda\\envs\\CV\\lib\\site-packages\\IPython\\core\\interactiveshell.py\", line 3458, in run_code\n",
      "    self.showtraceback(running_compiled_code=True)\n",
      "  File \"D:\\Anaconda\\envs\\CV\\lib\\site-packages\\IPython\\core\\interactiveshell.py\", line 2064, in showtraceback\n",
      "    value, tb, tb_offset=tb_offset)\n",
      "  File \"D:\\Anaconda\\envs\\CV\\lib\\site-packages\\IPython\\core\\ultratb.py\", line 1368, in structured_traceback\n",
      "    self, etype, value, tb, tb_offset, number_of_lines_of_context)\n",
      "  File \"D:\\Anaconda\\envs\\CV\\lib\\site-packages\\IPython\\core\\ultratb.py\", line 1268, in structured_traceback\n",
      "    self, etype, value, tb, tb_offset, number_of_lines_of_context\n",
      "  File \"D:\\Anaconda\\envs\\CV\\lib\\site-packages\\IPython\\core\\ultratb.py\", line 1125, in structured_traceback\n",
      "    tb_offset)\n",
      "  File \"D:\\Anaconda\\envs\\CV\\lib\\site-packages\\IPython\\core\\ultratb.py\", line 1082, in format_exception_as_a_whole\n",
      "    last_unique, recursion_repeat = find_recursion(orig_etype, evalue, records)\n",
      "  File \"D:\\Anaconda\\envs\\CV\\lib\\site-packages\\IPython\\core\\ultratb.py\", line 382, in find_recursion\n",
      "    return len(records), 0\n",
      "TypeError: object of type 'NoneType' has no len()\n",
      "\n",
      "During handling of the above exception, another exception occurred:\n",
      "\n",
      "Traceback (most recent call last):\n",
      "  File \"D:\\Anaconda\\envs\\CV\\lib\\site-packages\\IPython\\core\\interactiveshell.py\", line 2061, in showtraceback\n",
      "    stb = value._render_traceback_()\n",
      "AttributeError: 'TypeError' object has no attribute '_render_traceback_'\n",
      "\n",
      "During handling of the above exception, another exception occurred:\n",
      "\n",
      "Traceback (most recent call last):\n",
      "  File \"D:\\Anaconda\\envs\\CV\\lib\\site-packages\\IPython\\core\\interactiveshell.py\", line 2944, in _run_cell\n",
      "    return runner(coro)\n",
      "  File \"D:\\Anaconda\\envs\\CV\\lib\\site-packages\\IPython\\core\\async_helpers.py\", line 68, in _pseudo_sync_runner\n",
      "    coro.send(None)\n",
      "  File \"D:\\Anaconda\\envs\\CV\\lib\\site-packages\\IPython\\core\\interactiveshell.py\", line 3170, in run_cell_async\n",
      "    interactivity=interactivity, compiler=compiler, result=result)\n",
      "  File \"D:\\Anaconda\\envs\\CV\\lib\\site-packages\\IPython\\core\\interactiveshell.py\", line 3380, in run_ast_nodes\n",
      "    self.showtraceback()\n",
      "  File \"D:\\Anaconda\\envs\\CV\\lib\\site-packages\\IPython\\core\\interactiveshell.py\", line 2064, in showtraceback\n",
      "    value, tb, tb_offset=tb_offset)\n",
      "  File \"D:\\Anaconda\\envs\\CV\\lib\\site-packages\\IPython\\core\\ultratb.py\", line 1368, in structured_traceback\n",
      "    self, etype, value, tb, tb_offset, number_of_lines_of_context)\n",
      "  File \"D:\\Anaconda\\envs\\CV\\lib\\site-packages\\IPython\\core\\ultratb.py\", line 1268, in structured_traceback\n",
      "    self, etype, value, tb, tb_offset, number_of_lines_of_context\n",
      "  File \"D:\\Anaconda\\envs\\CV\\lib\\site-packages\\IPython\\core\\ultratb.py\", line 1143, in structured_traceback\n",
      "    chained_exceptions_tb_offset)\n",
      "  File \"D:\\Anaconda\\envs\\CV\\lib\\site-packages\\IPython\\core\\ultratb.py\", line 1082, in format_exception_as_a_whole\n",
      "    last_unique, recursion_repeat = find_recursion(orig_etype, evalue, records)\n",
      "  File \"D:\\Anaconda\\envs\\CV\\lib\\site-packages\\IPython\\core\\ultratb.py\", line 382, in find_recursion\n",
      "    return len(records), 0\n",
      "TypeError: object of type 'NoneType' has no len()\n",
      "\n",
      "During handling of the above exception, another exception occurred:\n",
      "\n",
      "Traceback (most recent call last):\n",
      "  File \"D:\\Anaconda\\envs\\CV\\lib\\site-packages\\IPython\\core\\interactiveshell.py\", line 2061, in showtraceback\n",
      "    stb = value._render_traceback_()\n",
      "AttributeError: 'TypeError' object has no attribute '_render_traceback_'\n",
      "\n",
      "During handling of the above exception, another exception occurred:\n",
      "\n",
      "Traceback (most recent call last):\n",
      "  File \"D:\\Anaconda\\envs\\CV\\lib\\site-packages\\IPython\\core\\ultratb.py\", line 1101, in get_records\n",
      "    return _fixed_getinnerframes(etb, number_of_lines_of_context, tb_offset)\n",
      "  File \"D:\\Anaconda\\envs\\CV\\lib\\site-packages\\IPython\\core\\ultratb.py\", line 248, in wrapped\n",
      "    return f(*args, **kwargs)\n",
      "  File \"D:\\Anaconda\\envs\\CV\\lib\\site-packages\\IPython\\core\\ultratb.py\", line 281, in _fixed_getinnerframes\n",
      "    records = fix_frame_records_filenames(inspect.getinnerframes(etb, context))\n",
      "  File \"D:\\Anaconda\\envs\\CV\\lib\\inspect.py\", line 1502, in getinnerframes\n",
      "    frameinfo = (tb.tb_frame,) + getframeinfo(tb, context)\n",
      "  File \"D:\\Anaconda\\envs\\CV\\lib\\inspect.py\", line 1460, in getframeinfo\n",
      "    filename = getsourcefile(frame) or getfile(frame)\n",
      "  File \"D:\\Anaconda\\envs\\CV\\lib\\inspect.py\", line 696, in getsourcefile\n",
      "    if getattr(getmodule(object, filename), '__loader__', None) is not None:\n",
      "  File \"D:\\Anaconda\\envs\\CV\\lib\\inspect.py\", line 733, in getmodule\n",
      "    if ismodule(module) and hasattr(module, '__file__'):\n",
      "  File \"D:\\Anaconda\\envs\\CV\\lib\\site-packages\\tensorflow\\__init__.py\", line 50, in __getattr__\n",
      "    module = self._load()\n",
      "  File \"D:\\Anaconda\\envs\\CV\\lib\\site-packages\\tensorflow\\__init__.py\", line 44, in _load\n",
      "    module = _importlib.import_module(self.__name__)\n",
      "  File \"D:\\Anaconda\\envs\\CV\\lib\\importlib\\__init__.py\", line 127, in import_module\n",
      "    return _bootstrap._gcd_import(name[level:], package, level)\n",
      "  File \"<frozen importlib._bootstrap>\", line 1006, in _gcd_import\n",
      "  File \"<frozen importlib._bootstrap>\", line 983, in _find_and_load\n",
      "  File \"<frozen importlib._bootstrap>\", line 965, in _find_and_load_unlocked\n",
      "ModuleNotFoundError: No module named 'tensorflow_core.estimator'\n"
     ]
    }
   ],
   "source": [
    "clf2 = RandomForestClassifier()\n",
    "\n",
    "full_train = np.array(full_train).reshape(7500,2048)\n",
    "full_test = np.array(full_test).reshape(1200,2048)\n",
    "\n",
    "inp = [0]*7500\n",
    "out = [1]*1200\n",
    "\n",
    "clf2.fit(full_train,inp)\n",
    "y = clf.score(full_test,out)\n",
    "y"
   ]
  },
  {
   "cell_type": "code",
   "execution_count": null,
   "id": "67690ebb",
   "metadata": {},
   "outputs": [],
   "source": []
  }
 ],
 "metadata": {
  "kernelspec": {
   "display_name": "Python 3 (ipykernel)",
   "language": "python",
   "name": "python3"
  },
  "language_info": {
   "codemirror_mode": {
    "name": "ipython",
    "version": 3
   },
   "file_extension": ".py",
   "mimetype": "text/x-python",
   "name": "python",
   "nbconvert_exporter": "python",
   "pygments_lexer": "ipython3",
   "version": "3.7.11"
  }
 },
 "nbformat": 4,
 "nbformat_minor": 5
}
